Workbook

Sheet البنوك
A1: اليوم | E1: الاثنين | G1: 25/6/2024
A2: البنك الاهلي هشام يوسف | D2: الاسكندرية هشام شركات | G2: البنوك والارصدة
A3: المبلغ | B3: التفاصيل | D3: المبلغ | E3: التفاصيل | G3: البنك | H3: الرصيد
A4: 87756 | B4: رصيد اول المدة | D4: 581261 | E4: رصيد اول المدة | G4: البنك الاهلي هشام | H4: =A25 -> 87756
G5: الاسكندرية هشام شركات | H5: =D25 -> 581261
G6: الاسكندرية يوسف يوسف | H6: =D43 -> 49846
G7: بنك مصر يوسف يوسف | H7: =A43 -> 80341
G8: بنك مصر الشرق | H8: =I43 -> 25881
G9: الاسكندرية الشرق | H9: =G43 -> 48099
G13: الرصيد النهائي | H13: =SUM(A25+D25+D43+A43+I43+G43) -> 873184
A25: =SUM(A4:A24) -> 87756 | B25: رصيد اخر المدة | D25: =SUM(D4:D24) -> 581261 | E25: رصيد اخر المدة | G25: =SUM(G16:G24) -> 0 | H25: رصيد اخر المدة | I25: =SUM(I16:I24) -> 0 | J25: رصيد اخر المدة
A26: بنك مصر يوسف شركات | D26: الاسكندرية يوسف يوسف | G26: الاسكندرية الشرق | I26: بنك مصر الشرق
A27: المبلغ | B27: التفاصيل | D27: المبلغ | E27: التفاصيل | G27: المبلغ | H27: التفاصيل | I27: المبلغ | J27: التفاصيل
A28: 80341 | B28: رصيد اول المدة | D28: 49846 | E28: رصيد اول المدة | G28: 48099 | H28: رصيد اول المدة | I28: 25881 | J28: رصيد اول المدة
A43: =SUM(A28:A42) -> 80341 | B43: رصيد اخر المدة | D43: =SUM(D28:D42) -> 49846 | E43: رصيد اخر المدة | G43: =SUM(G28:G42) -> 48099 | H43: رصيد اخر المدة | I43: =SUM(I28:I42) -> 25881 | J43: رصيد اخر المدة

Sheet الصفحه الرئسية
C3: الارصدة
F7: =SUM(F10:F31) -> 2526323927 | G7: =SUM(G10:G31) -> 2531358292 | H7: =G7-F7 -> 5034365
D8: الرقم | E8: اسم البنك | F8: الحركة | H8: الرصيد
F9: مدين | G9: دائن | H9: =H7 -> 5034365
D10: 1 | E10: ='1'!C3 -> بنك الاهلى (سليم) | F10: ='1'!E5 -> 335251450 | G10: ='1'!F5 -> 335252020 | H10: ='1'!G5 -> 570 | I10: الاهلى (سليم)
D11: 2 | E11: ='2'!C3 -> بنك الاسكندرية هشام شركات | F11: ='2'!E5 -> 685056921 | G11: ='2'!F5 -> 685132190 | H11: ='2'!G5 -> 75269 | I11: الاسكندرية هشام | J11: `
D12: 3 | E12: ='3'!C3 -> بنك الاسكندرية يوسف شركات | F12: ='3'!E5 -> 584195041 | G12: ='3'!F5 -> 587688630 | H12: ='3'!G5 -> 3493589 | I12: الاسكندرية يوسف
D13: 4 | E13: ='4'!C3 -> بنك مصر يوسف شركات | F13: ='4'!E5 -> 233401472 | G13: ='4'!F5 -> 233402047 | H13: ='4'!G5 -> 575 | I13: مصر يوسف
D14: 5 | E14: ='5'!C3 -> بنك مصر الشرق شركات | F14: ='5'!E5 -> 409583649 | G14: ='5'!F5 -> 410082907 | H14: ='5'!G5 -> 499258 | I14: مصر الشرق
D15: 6 | E15: ='6'!C3 -> بنك الاسكندرية الشرق شركات | F15: ='6'!E5 -> 128889927 | G15: ='6'!F5 -> 128890052 | H15: ='6'!G5 -> 125 | I15: الاسكندريه الشرق
D16: 7 | E16: ='7'!C3 -> بنك ابو ظبى (الاول) | F16: ='7'!E5 -> 49925867 | G16: ='7'!F5 -> 50019451 | H16: ='7'!G5 -> 93584 | I16: ابو ظبى (الاول)
D17: 8 | E17: ='8'!C3 -> انستا باى بنك الاسكندريه | F17: ='8'!E5 -> 16356752 | G17: ='8'!F5 -> 16362658 | H17: ='8'!G5 -> 5906 | I17: انستا باى بنك الاسكندريه
D18: 9 | E18: ='9'!C3 -> انستا باي بنك الاهلى | F18: ='9'!E5 -> 25834066 | G18: ='9'!F5 -> 26357776 | H18: ='9'!G5 -> 523710 | I18: انستا باى بنك الاهلى
D19: 10 | E19: ='10'!C3 -> فودافون كاش | F19: ='10'!E5 -> 4078825 | G19: ='10'!F5 -> 4090134 | H19: ='10'!G5 -> 11309 | I19: فودافون كاش | J19: `
D20: 11 | E20: ='11'!C3 -> اتصالات كاش | F20: ='11'!E5 -> 3008032 | G20: ='11'!F5 -> 3038999 | H20: ='11'!G5 -> 30967 | I20: اتصالات كاش
D21: 12 | E21: ='12'!C3 -> البريد المصرى | F21: ='12'!E5 -> 15457953 | G21: ='12'!F5 -> 15593264 | H21: ='12'!G5 -> 135311 | I21: البريد المصرى
D22: 13 | E22: ='13'!C3 -> فودافون كاش (جيمى) | F22: ='13'!E5 -> 1692263 | G22: ='13'!F5 -> 1709284 | H22: ='13'!G5 -> 17021 | I22: فودافون كاش (جيمى)
D23: 14 | E23: ='14'!C3 -> فودافون كاش (يوسف يوسف) | F23: ='14'!E5 -> 29200 | G23: ='14'!F5 -> 53195 | H23: ='14'!G5 -> 23995 | I23: فودافون كاش (يوسف يوسف)
D24: 15 | E24: الاهلى (يوسف يوسف) | F24: ='15'!E5 -> 20055180 | G24: ='15'!F5 -> 20056830 | H24: ='15'!G5 -> 1650 | I24: الاهلى (يوسف يوسف)
D25: 16 | E25: ='16'!C3 -> بنك العقارى المصرى العربى | F25: ='16'!E5 -> 2950000 | G25: ='16'!F5 -> 3000000 | H25: ='16'!G5 -> 50000 | I25: العقارى المصرى العربى
D26: 17 | E26: ='17'!C3 -> فودافون كاش ( احمد علاء ) | F26: ='17'!E5 -> 67329 | G26: ='17'!F5 -> 67355 | H26: ='17'!G5 -> 26 | I26: فودافون كاش ( احمد علاء )
D27: 18 | E27: ='18'!C3 -> بنك الأسكان والتعمير | F27: ='18'!E5 -> 10490000 | G27: ='18'!F5 -> 10561500 | H27: ='18'!G5 -> 71500 | I27: بنك الأسكان والتعمير
D28: 19 | E28: ='19'!C3 -> 0 | I28: 0
D29: 20 | E29: ='20'!C3 -> 0 | I29: 0
D30: 21 | E30: ='21'!C3 -> 0 | I30: 0
D31: 22 | E31: ='22'!C3 -> 0 | I31: 0

Sheet 1
C3: بنك الاهلى (سليم)
E5: =SUM(E8:E2000) -> 335251450 | F5: =SUM(F8:F2000) -> 335252020 | G5: =F5-E5 -> 570 | I5: الصفحة الرئيسية
C6: التاريخ | D6: الاسم | E6: الحركة | G6: الرصيد
E7: مدين | F7: دائن
C8: 24/7/2024 | D8: رصيد افتتاحي | F8: 1291414 | G8: =F8-E8 -> 1291414
C9: 24/7/2024 | D9: هشام يوسف مصاريف | E9: 659 | G9: =F9-E9+G8 -> 1290755
C10: 24/7/2024 | D10: صفوت مطحن الدوليه | F10: 800000 | G10: =F10-E10+G9 -> 2090755
C11: 24/7/2024 | D11: صفوت مطحن الدوليه | F11: 900000 | G11: =F11-E11+G10 -> 2990755
C12: 24/7/2024 | D12: اعالي البحار | E12: 1831065 | G12: =F12-E12+G11 -> 1159690
C13: 24/7/2024 | D13: مقدم حجز حديد الدكتور عمرو | F13: 60000 | G13: =F13-E13+G12 -> 1219690
C14: 25/7/2024 | D14: هشام يوسف مصاريف | E14: 200 | G14: =F14-E14+G13 -> 1219490
C15: 25/7/2024 | D15: هشام يوسف مصاريف | E15: 840 | G15: =F15-E15+G14 -> 1218650
C16: 27/7/2024 | D16: اسمنت اسيوط | E16: 120000 | G16: =F16-E16+G15 -> 1098650
C17: 27/7/2024 | D17: اسمنت اسيوط | E17: 101000 | G17: =F17-E17+G16 -> 997650
C18: 28/7/2024 | D18: احمد فوزى المهركه | F18: 5 | G18: =F18-E18+G17 -> 997655
C19: 28/7/2024 | D19: احمد فوزى المهركه | F19: 70000 | G19: =F19-E19+G18 -> 1067655
C20: 28/7/2024 | D20: احمد فوزى المهركه | F20: 70000 | G20: =F20-E20+G19 -> 1137655
C21: 28/7/2024 | D21: اسمنت اسيوط | E21: 125000 | G21: =F21-E21+G20 -> 1012655
C22: 28/7/2024 | D22: حسام زكي الساحل | F22: 1810000 | G22: =F22-E22+G21 -> 2822655
C23: 28/7/2024 | D23: المتحده لتوريد وتوزيع حديد التسليح ومواد البناء | E23: 1840000 | G23: =F23-E23+G22 -> 982655
C24: 28/7/2024 | D24: اعالي البحار | E24: 394963 | G24: =F24-E24+G23 -> 587692
C25: 29/7/2024 | D25: تحويل من البنك الاهلي | F25: 1500000 | G25: =F25-E25+G24 -> 2087692
C26: 29/7/2024 | D26: محمد محمد رمضان | E26: 1930000 | G26: =F26-E26+G25 -> 157692
C27: 29/7/2024 | D27: تبع اسعد جورج | E27: 20000 | G27: =F27-E27+G26 -> 137692
C28: 29/7/2024 | D28: تبع اسعد جورج | E28: 25000 | G28: =F28-E28+G27 -> 112692
C29: 30/7/2024 | D29: الشيخ خالد مصطفي | F29: 70000 | G29: =F29-E29+G28 -> 182692
C30: 30/7/2024 | D30: الشيخ خالد مصطفي | F30: 28000 | G30: =F30-E30+G29 -> 210692
C31: 30/7/2024 | D31: انستا باي | E31: 35000 | G31: =F31-E31+G30 -> 175692
C32: 31/7/2024 | D32: انستا باي | E32: 120000 | G32: =F32-E32+G31 -> 55692
C33: 31/7/2024 | D33: انستا باي | E33: 48000 | G33: =F33-E33+G32 -> 7692
C34: 31/7/2024 | D34: الشيخ خالد مصطفي | F34: 266750 | G34: =F34-E34+G33 -> 274442
C35: 31/7/2024 | D35: نقدي | E35: 5403 | G35: =F35-E35+G34 -> 269039
C36: 31/7/2024 | D36: مياه مخزن اسيوط الجديدة | E36: 879 | G36: =F36-E36+G35 -> 268160
C37: 31/7/2024 | D37: مطحن الدولية | F37: 650000 | G37: =F37-E37+G36 -> 918160
C38: 31/7/2024 | D38: فائده مدينه | F38: 4582 | G38: =F38-E38+G37 -> 922742
C39: 31/7/2024 | D39: فائده مدينه | E39: 1778 | G39: =F39-E39+G38 -> 920964
C40: 45505 | D40: تحويل من الشيخ خالد الرحاب | F40: 12000 | G40: =F40-E40+G39 -> 932964
C41: 45505 | D41: تحويل من الشيخ خالد الرحاب | F41: 8000 | G41: =F41-E41+G40 -> 940964
C42: 45505 | D42: بنزين | E42: 500 | G42: =F42-E42+G41 -> 940464
C43: 45505 | D43: صفوت مطحن الدوليه | F43: 516000 | G43: =F43-E43+G42 -> 1456464
...

Sheet 2
C3: بنك الاسكندرية هشام شركات
E5: =SUM(E8:E3000) -> 685056921 | F5: =SUM(F8:F3000) -> 685132190 | G5: =F5-E5 -> 75269 | I5: الصفحة الرئيسية
C6: التاريخ | D6: الاسم | E6: الحركة | G6: الرصيد
E7: مدين | F7: دائن
C8: 24/7/2024 | D8: رصيد افتتاحي | F8: 3661885 | G8: =F8-E8 -> 3661885
C9: 24/7/2024 | D9: شيك قطعة(5) تجاري اداري | E9: 1078010 | G9: =F9-E9+G8 -> 2583875
C10: 24/7/2024 | D10: احمد ثابت تايسون | F10: 361000 | G10: =F10-E10+G9 -> 2944875
C11: 24/7/2024 | D11: اسمنت التعمير | E11: 432075 | G11: =F11-E11+G10 -> 2512800
C12: 24/7/2024 | D12: احمد سليمان فهمي الفيما | E12: 250000 | G12: =F12-E12+G11 -> 2262800
C13: 28/7/2024 | D13: حديد عز السادات | E13: 2050000 | G13: =F13-E13+G12 -> 212800
C14: 28/7/2024 | D14: محمد مختار | F14: 210000 | G14: =F14-E14+G13 -> 422800
C15: 28/7/2024 | D15: ايداع نقدي | F15: 139200 | G15: =F15-E15+G14 -> 562000
C16: 28/7/2024 | D16: ايداع نقدي | F16: 50800 | G16: =F16-E16+G15 -> 612800
C17: 28/7/2024 | D17: ايداع نقدي | F17: 347200 | G17: =F17-E17+G16 -> 960000
C18: 28/7/2024 | D18: ايداع نقدي | F18: 950400 | G18: =F18-E18+G17 -> 1910400
C19: 28/7/2024 | D19: ايداع نقدي | F19: 2200 | G19: =F19-E19+G18 -> 1912600
C20: 29/7/2024 | D20: تحويل الي البنك الاهلي | E20: 1500075 | G20: =F20-E20+G19 -> 412525
C21: 45502 | D21: ايداع نقدي | F21: 25000 | G21: =F21-E21+G20 -> 437525
C22: 45502 | D22: ايداع نقدي | F22: 20000 | G22: =F22-E22+G21 -> 457525
C23: 45502 | D23: ايداع نقدي | F23: 1550000 | G23: =F23-E23+G22 -> 2007525
C24: 45502 | D24: ايداع نقدي | F24: 20000 | G24: =F24-E24+G23 -> 2027525
C25: 45502 | D25: ايداع نقدي | F25: 20000 | G25: =F25-E25+G24 -> 2047525
C26: 45502 | D26: ايداع نقدي | F26: 250000 | G26: =F26-E26+G25 -> 2297525
C27: 45502 | D27: ايداع نقدي | F27: 15500 | G27: =F27-E27+G26 -> 2313025
C28: 45502 | D28: حديد عز السادات | E28: 2050000 | G28: =F28-E28+G27 -> 263025
C29: 30/7/2024 | D29: ايداع نقدي | F29: 120200 | G29: =F29-E29+G28 -> 383225
C30: 30/7/2024 | D30: بنك الاسكندرية هشام الشخصي | F30: 300000 | G30: =F30-E30+G29 -> 683225
C31: 30/7/2024 | D31: بنك الاسكندرية يوسف | F31: 723000 | G31: =F31-E31+G30 -> 1406225
C32: 30/7/2024 | D32: بنك مصر يوسف | F32: 368000 | G32: =F32-E32+G31 -> 1774225
C33: 30/7/2024 | D33: بنك الاسكندرية الشرق | F33: 74000 | G33: =F33-E33+G32 -> 1848225
C34: 30/7/2024 | D34: بنك مصر الشرق | F34: 50000 | G34: =F34-E34+G33 -> 1898225
C35: 30/7/2024 | D35: احمد سليمان فهمي الفيما | F35: 55000 | G35: =F35-E35+G34 -> 1953225
C36: 30/7/2024 | D36: انستا باي | F36: 47000 | G36: =F36-E36+G35 -> 2000225
C37: 30/7/2024 | D37: احمد تايسون | E37: 2000075 | G37: =F37-E37+G36 -> 150
C38: 31/7/2024 | D38: مصاريف تشغيلية | E38: 150 | G38: =F38-E38+G37 -> 0
C39: 31/7/2024 | D39: ايداع نقدي | F39: 320200 | G39: =F39-E39+G38 -> 320200
C40: 31/7/2024 | D40: ايداع نقدي | F40: 1000000 | G40: =F40-E40+G39 -> 1320200
C41: 31/7/2024 | D41: احمد سليمان فهمي الفيما | E41: 1000075 | G41: =F41-E41+G40 -> 320125
C42: 31/7/2024 | D42: فوائد | F42: 8777 | G42: =F42-E42+G41 -> 328902
C43: 45505 | D43: مصاريف كشف حساب | E43: 50 | G43: =F43-E43+G42 -> 328852
...

Sheet 3
C3: بنك الاسكندرية يوسف شركات
E5: =SUM(E8:E2000) -> 584195041 | F5: =SUM(F8:F2000) -> 587688630 | G5: =F5-E5 -> 3493589 | I5: الصفحة الرئيسية
C6: التاريخ | D6: الاسم | E6: الحركة | G6: الرصيد
E7: مدين | F7: دائن
C8: 24/7/2024 | D8: رصيد افتتاحي | F8: 1315534 | G8: =F8-E8 -> 1315534
C9: 24/7/2024 | D9: محمود شمتان | F9: 47950 | G9: =F9-E9+G8 -> 1363484
C10: 28/7/2024 | D10: منصور سليمان | E10: 850000 | G10: =F10-E10+G9 -> 513484
C11: 28/7/2024 | D11: سالم ابو لافي | F11: 10 | G11: =F11-E11+G10 -> 513494
C12: 28/7/2024 | D12: سالم ابو لافي | F12: 50000 | G12: =F12-E12+G11 -> 563494
C13: 28/7/2024 | D13: اسعد جورج | F13: 90000 | G13: =F13-E13+G12 -> 653494
C14: 45501 | D14: مينا مكي حديد | F14: 300000 | G14: =F14-E14+G13 -> 953494
C15: 45501 | D15: الرضا ستيل | E15: 953000 | G15: =F15-E15+G14 -> 494
C16: 29/7/2024 | D16: ايداع نقدي | F16: 134930 | G16: =F16-E16+G15 -> 135424
C17: 29/7/2024 | D17: ايداع نقدي | F17: 400000 | G17: =F17-E17+G16 -> 535424
C18: 29/7/2024 | D18: راشد الوسطي | F18: 182500 | G18: =F18-E18+G17 -> 717924
C19: 29/7/2024 | D19: ايداع نقدي | F19: 274800 | G19: =F19-E19+G18 -> 992724
C20: 29/7/2024 | D20: ايداع نقدي | F20: 407450 | G20: =F20-E20+G19 -> 1400174
C21: 29/7/2024 | D21: سالم ابو لافي | F21: 50000 | G21: =F21-E21+G20 -> 1450174
C22: 29/7/2024 | D22: سالم ابو لافي | F22: 50000 | G22: =F22-E22+G21 -> 1500174
C23: 29/7/2024 | D23: ايداع نقدي | F23: 318700 | G23: =F23-E23+G22 -> 1818874
C24: 29/7/2024 | D24: ايداع نقدي | F24: 107120 | G24: =F24-E24+G23 -> 1925994
C25: 45502 | D25: الرضا ستيل | E25: 3000000 | G25: =F25-E25+G24 -> -1074006
C26: 45502 | D26: ايداع نقدي | F26: 450000 | G26: =F26-E26+G25 -> -624006
C27: 45502 | D27: ايداع نقدي | F27: 600000 | G27: =F27-E27+G26 -> -24006
C28: 45502 | D28: ايداع نقدي | F28: 372100 | G28: =F28-E28+G27 -> 348094
C29: 45502 | D29: مينا مكي | F29: 200000 | G29: =F29-E29+G28 -> 548094
C30: 30/7/2024 | D30: محمد اسماعيل | F30: 25000 | G30: =F30-E30+G29 -> 573094
C31: 30/7/2024 | D31: مينا مكي | F31: 150000 | G31: =F31-E31+G30 -> 723094
C32: 30/7/2024 | D32: الاسكندرية هشام يوسف شركات | E32: 723000 | G32: =F32-E32+G31 -> 94
C33: 31/7/2024 | D33: مصاريف تشغيلية | E33: 60 | G33: =F33-E33+G32 -> 34
C34: 31/7/2024 | D34: اسعد جورج | F34: 100000 | G34: =F34-E34+G33 -> 100034
C35: 31/7/2024 | D35: عاطف الزاوية | F35: 50 | G35: =F35-E35+G34 -> 100084
C36: 31/7/2024 | D36: عاطف الزاوية | F36: 50100 | G36: =F36-E36+G35 -> 150184
C37: 45505 | D37: حسام زكي الساحل | F37: 290000 | G37: =F37-E37+G36 -> 440184
C38: 45505 | D38: الي يوسف يوسف | E38: 50075 | G38: =F38-E38+G37 -> 390109
C39: 45508 | D39: سيد عبدالعزيز | F39: 10 | G39: =F39-E39+G38 -> 390119
C40: 45508 | D40: سيد عبدالعزيز | F40: 15000 | G40: =F40-E40+G39 -> 405119
C41: 45509 | D41: الي الشركه الماسيه | E41: 400000 | G41: =F41-E41+G40 -> 5119
C42: 45509 | D42: ايداع نقدي | F42: 135000 | G42: =F42-E42+G41 -> 140119
C43: 45509 | D43: ايداع نقدي | F43: 1693620 | G43: =F43-E43+G42 -> 1833739
...

Sheet 4
C3: بنك مصر يوسف شركات
E5: =SUM(E8:E1003) -> 233401472 | F5: =SUM(F8:F1003) -> 233402047 | G5: =F5-E5 -> 575 | I5: الصفحة الرئيسية
C6: التاريخ | D6: الاسم | E6: الحركة | G6: الرصيد
E7: مدين | F7: دائن
C8: 24/7/2024 | D8: رصيد افتتاحي | F8: 529991 | G8: =F8-E8 -> 529991
C9: 24/7/2024 | D9: صفوت مطحن الدوليه | F9: 600000 | G9: =F9-E9+G8 -> 1129991
C10: 24/7/2024 | D10: حسام زكي الساحل | F10: 250000 | G10: =F10-E10+G9 -> 1379991
C11: 24/7/2024 | D11: حسام زكي الساحل | F11: 24500 | G11: =F11-E11+G10 -> 1404491
C12: 27/7/2024 | D12: اعالي البحار | E12: 1400000 | G12: =F12-E12+G11 -> 4491
C13: 28/7/2024 | D13: حسام زكي الساحل | F13: 100000 | G13: =F13-E13+G12 -> 104491
C14: 28/7/2024 | D14: وليد توفيق | F14: 127500 | G14: =F14-E14+G13 -> 231991
C15: 28/7/2024 | D15: جمال سيد | F15: 740000 | G15: =F15-E15+G14 -> 971991
C16: 28/7/2027 | D16: الرضا ستيل | E16: 971000 | G16: =F16-E16+G15 -> 991
C17: 29/7/2024 | D17: جمال سيد | F17: 167500 | G17: =F17-E17+G16 -> 168491
C18: 29/7/2024 | D18: شنوده نظمي | F18: 30000 | G18: =F18-E18+G17 -> 198491
C19: 30/7/2024 | D19: حسام زكي الساحل | F19: 170000 | G19: =F19-E19+G18 -> 368491
C20: 30/7/2024 | D20: بنك الاسكندرية هشام يوسف | E20: 368150 | G20: =F20-E20+G19 -> 341
C21: 45508 | D21: حسام زكي الساحل | F21: 500000 | G21: =F21-E21+G20 -> 500341
C22: 45509 | D22: حسام زكي الساحل | F22: 300000 | G22: =F22-E22+G21 -> 800341
C23: 45509 | D23: خالد الرحاب | F23: 250000 | G23: =F23-E23+G22 -> 1050341
C24: 45509 | D24: ولد مكي | F24: 100000 | G24: =F24-E24+G23 -> 1150341
C25: 45509 | D25: توريد الماسيه | E25: 1150000 | G25: =F25-E25+G24 -> 341
C26: 45509 | D26: جمال سيد | F26: 112500 | G26: =F26-E26+G25 -> 112841
C27: 45509 | D27: صفوت مطحن الدوليه | E27: 20000 | G27: =F27-E27+G26 -> 92841
C28: 45510 | D28: حسام زكي الساحل | F28: 300000 | G28: =F28-E28+G27 -> 392841
C29: 45510 | D29: مصروفات | E29: 50 | G29: =F29-E29+G28 -> 392791
C30: 45512 | D30: احمد سليمان | F30: 900000 | G30: =F30-E30+G29 -> 1292791
C31: 45512 | D31: خالد الرحاب | F31: 26400 | G31: =F31-E31+G30 -> 1319191
C32: 45515 | D32: حسام زكي الساحل | F32: 150000 | G32: =F32-E32+G31 -> 1469191
C33: 45515 | D33: حسام زكي الساحل | F33: 140000 | G33: =F33-E33+G32 -> 1609191
C34: 45515 | D34: خالد الرحاب | F34: 50000 | G34: =F34-E34+G33 -> 1659191
C35: 45515 | D35: احمد سليمان | E35: 1600000 | G35: =F35-E35+G34 -> 59191
C36: 45515 | D36: خالد الرحاب | F36: 40000 | G36: =F36-E36+G35 -> 99191
C37: 45515 | D37: خالد الرحاب | F37: 10 | G37: =F37-E37+G36 -> 99201
C38: 45515 | D38: خالد الرحاب | F38: 50000 | G38: =F38-E38+G37 -> 149201
C39: 45515 | D39: خالد الرحاب | F39: 50000 | G39: =F39-E39+G38 -> 199201
C40: 45515 | D40: خالد الرحاب | F40: 2200 | G40: =F40-E40+G39 -> 201401
C41: 45515 | D41: خالد الرحاب | F41: 43200 | G41: =F41-E41+G40 -> 244601
C42: 45515 | D42: خالد الرحاب | F42: 48375 | G42: =F42-E42+G41 -> 292976
C43: 45516 | D43: مينا مكي | F43: 70000 | G43: =F43-E43+G42 -> 362976
...

Sheet 5
C3: بنك مصر الشرق شركات
E5: =SUM(E8:E2000) -> 409583649 | F5: =SUM(F8:F2000) -> 410082907 | G5: =F5-E5 -> 499258 | I5: الصفحة الرئيسية
C6: التاريخ | D6: الاسم | E6: الحركة | G6: الرصيد
E7: مدين | F7: دائن
C8: 24/7/2024 | D8: رصيد افتتاحي | F8: 453 | G8: =F8-E8 -> 453
C9: 45484 | D9: شريف الغول | F9: 52000 | G9: =F9-E9+G8 -> 52453
C10: 30/7/2024 | D10: ضرايب شهر 6 | E10: 1439 | G10: =F10-E10+G9 -> 51014
C11: 30/7/2024 | D11: بنك الاسكندرية هشام يوسف | E11: 50100 | G11: =F11-E11+G10 -> 914
C12: 45481 | D12: المهندس فرح | F12: 250000 | G12: =F12-E12+G11 -> 250914
C13: 45516 | D13: من صابر جابر مهران هياخدهم نقدي | F13: 557000 | G13: =F13-E13+G12 -> 807914
C14: 13/8/2024 | D14: المهندس فرح | F14: 75000 | G14: =F14-E14+G13 -> 882914
C15: 13/8/2024 | D15: الرضا ستيل | E15: 882000 | G15: =F15-E15+G14 -> 914
C16: 45523 | D16: رضا ناجح | F16: 199400 | G16: =F16-E16+G15 -> 200314
C17: 45524 | D17: محمد ابو سته | F17: 72000 | G17: =F17-E17+G16 -> 272314
C18: 45526 | D18: محمد ابو سته | F18: 63750 | G18: =F18-E18+G17 -> 336064
C19: 45526 | D19: الرضا ستيل | E19: 335000 | G19: =F19-E19+G18 -> 1064
C20: 45531 | D20: اكتوبر استيل | F20: 80000 | G20: =F20-E20+G19 -> 81064
C21: 45532 | D21: الشيخ سيد عبد العزيز | F21: 30000 | G21: =F21-E21+G20 -> 111064
C22: 45532 | D22: مصطفى ابو عوف ( هياخدهم نقدى) | F22: 400000 | G22: =F22-E22+G21 -> 511064
C23: 45533 | D23: الشيخ سيد عبد العزيز | F23: 16500 | G23: =F23-E23+G22 -> 527564
C24: 45533 | D24: الشركه الماسيه | E24: 526000 | G24: =F24-E24+G23 -> 1564
C25: 45533 | D25: بنزين يوسف مصاريف | E25: 935 | G25: =F25-E25+G24 -> 629
C26: 45536 | D26: محمد شباره(70 طن سهم عاده ورق ) | F26: 137900 | G26: =F26-E26+G25 -> 138529
C27: 45536 | D27: ضرايب شهر 7 | E27: 1718 | G27: =F27-E27+G26 -> 136811
C28: 45545 | D28: محمد شباره(210 طن سهم عاده ورق ) | F28: 451500 | G28: =F28-E28+G27 -> 588311
C29: 45546 | D29: رضا ناجح | F29: 500000 | G29: =F29-E29+G28 -> 1088311
C30: 45546 | D30: رضا ناجح | F30: 500000 | G30: =F30-E30+G29 -> 1588311
C31: 45546 | D31: بنزين يوسف مصاريف | E31: 885 | G31: =F31-E31+G30 -> 1587426
C32: 45547 | D32: عهده سيد فرحان ( تصليح اللودر ) | E32: 18000 | G32: =F32-E32+G31 -> 1569426
C33: 45547 | D33: احمد الامام (خدهم نقدى) | F33: 800000 | G33: =F33-E33+G32 -> 2369426
C34: 45547 | D34: الرضا ستيل | E34: 2369000 | G34: =F34-E34+G33 -> 426
C35: 45556 | D35: احمد همام (هياخدهم نقدى) | F35: 1000000 | G35: =F35-E35+G34 -> 1000426
C36: 45557 | D36: عاطف المسعودى | F36: 87800 | G36: =F36-E36+G35 -> 1088226
C37: 45559 | D37: سليم يوسف مصاريف | E37: 162000 | G37: =F37-E37+G36 -> 926226
C38: 45559 | D38: احمد همام | E38: 926000 | G38: =F38-E38+G37 -> 226
C39: 45564 | D39: عاطف المسعودى | F39: 40000 | G39: =F39-E39+G38 -> 40226
C40: 45564 | D40: الى الاهلى هشام شركات | E40: 40000 | G40: =F40-E40+G39 -> 226
C41: 45565 | D41: مصروفات | E41: 80 | G41: =F41-E41+G40 -> 146
C42: 45565 | D42: عاطف المسعودى | F42: 13000 | G42: =F42-E42+G41 -> 13146
C43: 45565 | D43: ضرايب قيمه مضافه | E43: 1158 | G43: =F43-E43+G42 -> 11988
...

Sheet 6
C3: بنك الاسكندرية الشرق شركات
E5: =SUM(E8:E999) -> 128889927 | F5: =SUM(F8:F999) -> 128890052 | G5: =F5-E5 -> 125 | I5: الصفحة الرئيسية
C6: التاريخ | D6: الاسم | E6: الحركة | G6: الرصيد
E7: مدين | F7: دائن
C8: 24/7/2024 | D8: رصيد افتتاحي | F8: 74399 | G8: =F8-E8 -> 74399
C9: 30/7/2024 | D9: بنك الاسكندرية هشام يوسف | E9: 74000 | G9: =F9-E9+G8 -> 399
C10: 31/7/2024 | D10: مصاريف تشغيلية | E10: 150 | G10: =F10-E10+G9 -> 249
C11: 31/7/2024 | D11: مصاريف كشف حساب | E11: 50 | G11: =F11-E11+G10 -> 199
C12: 31/7/2024 | D12: فوائد | F12: 174 | G12: =F12-E12+G11 -> 373
C13: 45511 | D13: ايداع من يعقوب موسي سمعان | F13: 75400 | G13: =F13-E13+G12 -> 75773
C14: 45526 | D14: تحويل الى اسكندريه هشام شركات | E14: 75000 | G14: =F14-E14+G13 -> 773
C15: 45533 | D15: مصاريف تشغيلية | E15: 200 | G15: =F15-E15+G14 -> 573
C16: 45533 | D16: فوائد بنكيه | F16: 218 | G16: =F16-E16+G15 -> 791
C17: 45551 | D17: صفوت سمعان (مقدم حديد جيوشى 35500) | F17: 210000 | G17: =F17-E17+G16 -> 210791
C18: 45551 | D18: صفوت سمعان | F18: 30000 | G18: =F18-E18+G17 -> 240791
C19: 45551 | D19: تحويل الى اسكندريه هشام شركات | E19: 240000 | G19: =F19-E19+G18 -> 791
C20: 45554 | D20: صفوت سمعان | F20: 250000 | G20: =F20-E20+G19 -> 250791
C21: 45554 | D21: صفوت سمعان | F21: 160000 | G21: =F21-E21+G20 -> 410791
C22: 45557 | D22: صفوت سمعان (25 الف من مصرف ابو ظبى ) | F22: 25000 | G22: =F22-E22+G21 -> 435791
C23: 45557 | D23: مصروفات بنكيه | E23: 15 | G23: =F23-E23+G22 -> 435776
C24: 45559 | D24: صفوت سمعان | F24: 50000 | G24: =F24-E24+G23 -> 485776
C25: 45559 | D25: صفوت سمعان | F25: 70000 | G25: =F25-E25+G24 -> 555776
C26: 45560 | D26: احمد همام | E26: 555000 | G26: =F26-E26+G25 -> 776
C27: 45564 | D27: صفوت سمعان | F27: 90000 | G27: =F27-E27+G26 -> 90776
C28: 45564 | D28: صفوت سمعان | F28: 190000 | G28: =F28-E28+G27 -> 280776
C29: 45564 | D29: صفوت سمعان | F29: 100 | G29: =F29-E29+G28 -> 280876
C30: 45564 | D30: صفوت سمعان | F30: 59000 | G30: =F30-E30+G29 -> 339876
C31: 45564 | D31: تحويل الى اسكندريه هشام شركات | E31: 339000 | G31: =F31-E31+G30 -> 876
C32: 45565 | D32: مصاريف تشغيلية | E32: 150 | G32: =F32-E32+G31 -> 726
C33: 45565 | D33: مصروفات بنكيه | E33: 50 | G33: =F33-E33+G32 -> 676
C34: 45565 | D34: صفوت سمعان | F34: 145000 | G34: =F34-E34+G33 -> 145676
C35: 45565 | D35: صفوت سمعان (بنك ابو ظبى بأسم ياسر ابو السعود) | F35: 50000 | G35: =F35-E35+G34 -> 195676
C36: 45565 | D36: مصروفات بنكيه | E36: 15 | G36: =F36-E36+G35 -> 195661
C37: 45565 | D37: فوائد بنكيه | F37: 516 | G37: =F37-E37+G36 -> 196177
C38: 45566 | D38: صفوت سمعان | F38: 90000 | G38: =F38-E38+G37 -> 286177
C39: 45566 | D39: صفوت سمعان | F39: 70000 | G39: =F39-E39+G38 -> 356177
C40: 45566 | D40: صفوت سمعان | F40: 50000 | G40: =F40-E40+G39 -> 406177
C41: 45567 | D41: صفوت سمعان | F41: 200000 | G41: =F41-E41+G40 -> 606177
C42: 45567 | D42: صفوت سمعان | F42: 22000 | G42: =F42-E42+G41 -> 628177
C43: 45568 | D43: مصروفات بنكيه | E43: 15 | G43: =F43-E43+G42 -> 628162
...

Sheet 7
C3: بنك ابو ظبى (الاول)
E5: =SUM(E8:E1000) -> 49925867 | F5: =SUM(F8:F1000) -> 50019451 | G5: =F5-E5 -> 93584 | I5: الصفحة الرئيسية
C6: التاريخ | D6: الاسم | E6: الحركة | G6: الرصيد
E7: مدين | F7: دائن
D8: رصيد افتتاحي | F8: 0 | G8: =F8-E8 -> 0
C9: 45634 | D9: من قطعه نجلاء | F9: 1000000 | G9: =F9-E9+G8 -> 1000000
C10: 45635 | D10: الى بنك الاسكندريه سليم | E10: 950000 | G10: =F10-E10+G9 -> 50000
C11: 45638 | D11: الحاج عبداللاه | F11: 600000 | G11: =F11-E11+G10 -> 650000
C12: 45638 | D12: من قطعه نجلاء | F12: 250000 | G12: =F12-E12+G11 -> 900000
C13: 45638 | D13: الى بنك الاسكندريه سليم | E13: 100000 | G13: =F13-E13+G12 -> 800000
C14: 45634 | D14: فيزا مشتريات ( ربط وديعه لأجل ) | E14: 10000 | G14: =F14-E14+G13 -> 790000
C15: 45638 | D15: مصروفات بنكيه | E15: 523 | G15: =F15-E15+G14 -> 789477
C16: 45648 | D16: الى بنك الاسكندريه سليم | E16: 750000 | G16: =F16-E16+G15 -> 39477
C17: 45648 | D17: مصروفات بنكيه | E17: 150 | G17: =F17-E17+G16 -> 39327
C18: 45648 | D18: المهندس فرح (شيك) | F18: 90000 | G18: =F18-E18+G17 -> 129327
C19: 45657 | D19: من بنك الاسكندريه يوسف | F19: 400000 | G19: =F19-E19+G18 -> 529327
C20: 45657 | D20: مصروفات بنكيه | E20: 25 | G20: =F20-E20+G19 -> 529302
C21: 45669 | D21: تحصيل شيك نجلاء | F21: 300000 | G21: =F21-E21+G20 -> 829302
C22: 45671 | D22: رضا ناجح (Prima life) | E22: 500000 | G22: =F22-E22+G21 -> 329302
C23: 45672 | D23: الى بنك الاسكندريه سليم | E23: 300000 | G23: =F23-E23+G22 -> 29302
C24: 45665 | D24: فوائد بنكيه | F24: 95 | G24: =F24-E24+G23 -> 29397
C25: 45677 | D25: اشرف عبدالمعطى (شيك) | F25: 100000 | G25: =F25-E25+G24 -> 129397
C26: 45686 | D26: الى بنك الاسكندريه سليم | E26: 128000 | G26: =F26-E26+G25 -> 1397
C27: 45689 | D27: مصروفات بنكيه | E27: 25 | G27: =F27-E27+G26 -> 1372
C28: 45697 | D28: فوائد بنكيه | F28: 96 | G28: =F28-E28+G27 -> 1468
C29: 45717 | D29: مصروفات بنكيه | E29: 25 | G29: =F29-E29+G28 -> 1443
C30: 45718 | D30: مصروفات بنكيه ( مديونيه فيزا المشتريات) | E30: 500 | G30: =F30-E30+G29 -> 943
C31: 45725 | D31: فوائد بنكيه | F31: 86 | G31: =F31-E31+G30 -> 1029
C32: 45729 | D32: اشرف عبدالمعطى (شيك) | F32: 100000 | G32: =F32-E32+G31 -> 101029
C33: 45732 | D33: اشرف عبدالمعطى (شيك) | F33: 200000 | G33: =F33-E33+G32 -> 301029
C34: 45735 | D34: اشرف عبدالمعطى (شيك) | F34: 100000 | G34: =F34-E34+G33 -> 401029
C35: 45739 | D35: الى بنك الاسكندريه سليم | E35: 100000 | G35: =F35-E35+G34 -> 301029
C36: 45739 | D36: الى بنك الاسكندريه سليم | E36: 300000 | G36: =F36-E36+G35 -> 1029
C37: 45740 | D37: اشرف عبدالمعطى (شيك) | F37: 200000 | G37: =F37-E37+G36 -> 201029
C38: 45743 | D38: خصم لتسديد مديونيه الفيزا | E38: 100 | G38: =F38-E38+G37 -> 200929
C39: 45750 | D39: مصاريف كشف حساب | E39: 25 | G39: =F39-E39+G38 -> 200904
C40: 45755 | D40: فائده بنكيه | F40: 95 | G40: =F40-E40+G39 -> 200999
C41: 45756 | D41: اشرف عبدالمعطى (شيك) | F41: 100000 | G41: =F41-E41+G40 -> 300999
C42: 45756 | D42: الى بنك الاسكندريه سليم | E42: 300000 | G42: =F42-E42+G41 -> 999
C43: 45764 | D43: ممدوح الملاخ (مقدم حديد السويس 36الف) | F43: 700000 | G43: =F43-E43+G42 -> 700999
...

Sheet 8
C3: انستا باى بنك الاسكندريه
E5: =SUM(E8:E1000) -> 16356752 | F5: =SUM(F8:F1000) -> 16362658 | G5: =F5-E5 -> 5906 | I5: الصفحة الرئيسية
C6: التاريخ | D6: الاسم | E6: الحركة | G6: الرصيد
E7: مدين | F7: دائن
D8: رصيد افتتاحي | F8: 5118 | G8: =F8-E8 -> 5118
C9: 45610 | D9: احمد فوزى المهركه | F9: 200000 | G9: =F9-E9+G8 -> 205118
C10: 45621 | D10: صفوت مطحن الدوليه | E10: 40000 | G10: =F10-E10+G9 -> 165118
C11: 45624 | D11: عمولة مايكل العربية الهيونداى | E11: 5000 | G11: =F11-E11+G10 -> 160118
C12: 45625 | D12: اسمنت اسيوط | E12: 31000 | G12: =F12-E12+G11 -> 129118
C13: 45632 | D13: مصروفات | E13: 280 | G13: =F13-E13+G12 -> 128838
C14: 45632 | D14: بنزين | E14: 1000 | G14: =F14-E14+G13 -> 127838
C15: 45633 | D15: قسط شقه الهضبه (شهر11) | E15: 52082 | G15: =F15-E15+G14 -> 75756
C16: 45633 | D16: قسط شقه الهضبه (شهر8) | E16: 55992 | G16: =F16-E16+G15 -> 19764
C17: 45634 | D17: سليم يوسف مصاريف | E17: 1298 | G17: =F17-E17+G16 -> 18466
C18: 45635 | D18: بنزين | E18: 1212 | G18: =F18-E18+G17 -> 17254
C19: 45637 | D19: شراء الطابعه | E19: 8416 | G19: =F19-E19+G18 -> 8838
C20: 45621 | D20: مصاريف يوسف سليم | E20: 2865 | G20: =F20-E20+G19 -> 5973
C21: 45647 | D21: محمد مختار (اخدهم نقدى)(سليم افراد) | F21: 1000000 | G21: =F21-E21+G20 -> 1005973
C22: 45647 | D22: الى بنك الاسكندريه سليم | E22: 50000 | G22: =F22-E22+G21 -> 955973
C23: 45647 | D23: الى بنك الاسكندريه سليم | E23: 70000 | G23: =F23-E23+G22 -> 885973
C24: 45649 | D24: الى بنك الاسكندريه سليم | E24: 880000 | G24: =F24-E24+G23 -> 5973
C25: 45657 | D25: من بنك الاسكندريه يوسف | F25: 500000 | G25: =F25-E25+G24 -> 505973
C26: 45659 | D26: الى بنك الاسكندريه سليم | E26: 500000 | G26: =F26-E26+G25 -> 5973
C27: 45657 | D27: مصاريف تشغيليه | E27: 330 | G27: =F27-E27+G26 -> 5643
C28: 45703 | D28: من بنك الاسكندريه سليم | F28: 67500 | G28: =F28-E28+G27 -> 73143
C29: 45703 | D29: تشطيب شقه مدينتى | E29: 67500 | G29: =F29-E29+G28 -> 5643
C30: 45708 | D30: من بنك الاسكندريه سليم | F30: 50000 | G30: =F30-E30+G29 -> 55643
C31: 45708 | D31: نولون احمد يوسف (نقله بدر) | E31: 15800 | G31: =F31-E31+G30 -> 39843
C32: 45709 | D32: سليم يوسف مصاريف | E32: 1130 | G32: =F32-E32+G31 -> 38713
C33: 45709 | D33: سليم يوسف مصاريف | E33: 143 | G33: =F33-E33+G32 -> 38570
C34: 45709 | D34: نولون اخو رجب (محمد عبده) | E34: 8400 | G34: =F34-E34+G33 -> 30170
C35: 45709 | D35: واصل شبرا | E35: 1000 | G35: =F35-E35+G34 -> 29170
C36: 45711 | D36: سليم يوسف مصاريف | E36: 800 | G36: =F36-E36+G35 -> 28370
C37: 45712 | D37: احمد سليمان فهمى (20 طن عاده مصريين) | F37: 64000 | G37: =F37-E37+G36 -> 92370
C38: 45715 | D38: محمد مختار (شيك) | F38: 300000 | G38: =F38-E38+G37 -> 392370
C39: 45715 | D39: سحب نقدى (واصل يوميه سليم) | E39: 250000 | G39: =F39-E39+G38 -> 142370
C40: 45721 | D40: الى بنك الاسكندريه سليم | E40: 70000 | G40: =F40-E40+G39 -> 72370
C41: 45721 | D41: الى بنك الاسكندريه سليم | E41: 50000 | G41: =F41-E41+G40 -> 22370
C42: 45723 | D42: نولون ترلة | E42: 15000 | G42: =F42-E42+G41 -> 7370
C43: 45723 | D43: سليم يوسف مصاريف | E43: 72 | G43: =F43-E43+G42 -> 7298
...

Sheet 9
C3: انستا باي بنك الاهلى
E5: =SUM(E8:E2000) -> 25834066 | F5: =SUM(F8:F2000) -> 26357776 | G5: =F5-E5 -> 523710 | I5: الصفحة الرئيسية
C6: التاريخ | D6: الاسم | E6: الحركة | G6: الرصيد
E7: مدين | F7: دائن
C8: 45474 | D8: رصيد افتتاحي | F8: 16344 | G8: =F8-E8 -> 16344
C9: 45474 | D9: مصاريف بنكيه | E9: 75 | G9: =F9-E9+G8 -> 16269
C10: 45477 | D10: من الاهلي شركات | F10: 250000 | G10: =F10-E10+G9 -> 266269
C11: 45477 | D11: سحب نقدي شيكات | E11: 250000 | G11: =F11-E11+G10 -> 16269
C12: 45481 | D12: محمود الفوال | F12: 40000 | G12: =F12-E12+G11 -> 56269
C13: 22/7/2024 | D13: مقدم سيستم الحسابات | E13: 10000 | G13: =F13-E13+G12 -> 46269
C14: 26/7/2024 | D14: نولون نقلتين صبحي | E14: 26400 | G14: =F14-E14+G13 -> 19869
C15: 27/7/2024 | D15: مقدم سيستم الحسابات | E15: 3500 | G15: =F15-E15+G14 -> 16369
C16: 28/7/2024 | D16: عمر الشهر العقاري في المصاريف | E16: 400 | G16: =F16-E16+G15 -> 15969
C17: 29/7/2024 | D17: احمد فاروق الحاسب في المصاريف | E17: 80 | G17: =F17-E17+G16 -> 15889
C18: 30/7/2024 | D18: من الاهلي شركات | F18: 35000 | G18: =F18-E18+G17 -> 50889
C19: 30/7/2024 | D19: الي الاسكندريه شركات | E19: 47000 | G19: =F19-E19+G18 -> 3889
C20: 30/7/2024 | D20: من الاهلي شركات | F20: 120000 | G20: =F20-E20+G19 -> 123889
C21: 30/7/2024 | D21: رضا ناجح سلف | E21: 70000 | G21: =F21-E21+G20 -> 53889
C22: 30/7/2024 | D22: من الاهلي شركات | F22: 48000 | G22: =F22-E22+G21 -> 101889
C23: 31/7/2024 | D23: رضا ناجح سلف | E23: 30000 | G23: =F23-E23+G22 -> 71889
C24: 31/7/2024 | D24: رضا ناجح سلف | E24: 70000 | G24: =F24-E24+G23 -> 1889
C25: 45505 | D25: عمر الشهر العقاري في المصاريف | E25: 200 | G25: =F25-E25+G24 -> 1689
C26: 45505 | D26: من الاهلي شركات | F26: 50000 | G26: =F26-E26+G25 -> 51689
C27: 45505 | D27: نولون 70 طن مقاوم حسام زكي | E27: 7000 | G27: =F27-E27+G26 -> 44689
C28: 45505 | D28: نولون 25 طن مقاوم علي فروجه راحت لجمال سيد | E28: 2750 | G28: =F28-E28+G27 -> 41939
C29: 45505 | D29: مصاريف بنكيه | E29: 10 | G29: =F29-E29+G28 -> 41929
C30: 45506 | D30: سليم يوسف مصاريف شحن نت | E30: 243 | G30: =F30-E30+G29 -> 41686
C31: 45506 | D31: نولون صبحي 50 طن عز | E31: 15500 | G31: =F31-E31+G30 -> 26186
C32: 45506 | D32: نولون نقله الحج عبداللاه جيوشي | E32: 14000 | G32: =F32-E32+G31 -> 12186
C33: 45507 | D33: سليم يوسف مصاريف واصل علي اسامه | E33: 3000 | G33: =F33-E33+G32 -> 9186
C34: 45507 | D34: من الاهلي شركات | F34: 50000 | G34: =F34-E34+G33 -> 59186
C35: 45507 | D35: علي اسامه حولهم فودافون كاش | E35: 18000 | G35: =F35-E35+G34 -> 41186
C36: 45508 | D36: ابانوب عفت | F36: 70000 | G36: =F36-E36+G35 -> 111186
C37: 45508 | D37: علي همام عموله المخزن | E37: 20000 | G37: =F37-E37+G36 -> 91186
C38: 45508 | D38: علي همام عموله المخزن | E38: 10000 | G38: =F38-E38+G37 -> 81186
C39: 45509 | D39: شراء لابتوب | E39: 9750 | G39: =F39-E39+G38 -> 71436
C40: 45510 | D40: مصاريف بنكيه | E40: 30 | G40: =F40-E40+G39 -> 71406
C41: 45511 | D41: يوسف يوسف تحويل لمحمود غلمي عهده تصليح | E41: 15000 | G41: =F41-E41+G40 -> 56406
C42: 45511 | D42: يوسف يوسف تحويل لمحمود غلمي عهده تصليح | E42: 15000 | G42: =F42-E42+G41 -> 41406
C43: 45512 | D43: نولون عاطف نقله عياد | E43: 15620 | G43: =F43-E43+G42 -> 25786
...

Sheet 10
C3: فودافون كاش
E5: =SUM(E8:E998) -> 4078825 | F5: =SUM(F8:F998) -> 4090134 | G5: =F5-E5 -> 11309 | I5: الصفحة الرئيسية
C6: التاريخ | D6: الاسم | E6: الحركة | G6: الرصيد
E7: مدين | F7: دائن
C8: 45476 | D8: رصيد افتتاحي | F8: 91120 | G8: =F8-E8 -> 91120
C9: 45475 | D9: سليم يوسف مصاريف | E9: 2505 | G9: =F9-E9+G8 -> 88615
C10: 45476 | D10: شحن محمود المهدي | E10: 115 | G10: =F10-E10+G9 -> 88500
C11: 45477 | D11: نولون سواق المخزن | E11: 4250 | G11: =F11-E11+G10 -> 84250
C12: 45477 | D12: نولون محمد سعد اخد الف جنيه من سيد ابوخريبه | E12: 15600 | G12: =F12-E12+G11 -> 68650
C13: 45478 | D13: نوالين صبحي | E13: 22700 | G13: =F13-E13+G12 -> 45950
C14: 45479 | D14: عهده شراء كاوتش لودر يد سيد الصقر | E14: 5000 | G14: =F14-E14+G13 -> 40950
C15: 45479 | D15: نولون 25طن راحت لجمال سيد اولاد ابراهيم | E15: 2625 | G15: =F15-E15+G14 -> 38325
C16: 45481 | D16: عهده عصام فتحي وهيب | E16: 500 | G16: =F16-E16+G15 -> 37825
C17: 45482 | D17: شحن كارت الكهربا | E17: 517 | G17: =F17-E17+G16 -> 37308
C18: 45482 | D18: عهده عصام فتحي وهيب | E18: 6400 | G18: =F18-E18+G17 -> 30908
C19: 45482 | D19: وليد توفيق | F19: 10000 | G19: =F19-E19+G18 -> 40908
C20: 45482 | D20: يوسف يوسف | E20: 3000 | G20: =F20-E20+G19 -> 37908
C21: 45483 | D21: يوسف يوسف | E21: 2700 | G21: =F21-E21+G20 -> 35208
C22: 45487 | D22: نولون احمد فرغلي نقله عبدالرحيم الساحل | E22: 2780 | G22: =F22-E22+G21 -> 32428
C23: 45487 | D23: طارق رفعت | E23: 5625 | G23: =F23-E23+G22 -> 26803
C24: 45488 | D24: نولون فارس اسامه | E24: 4425 | G24: =F24-E24+G23 -> 22378
C25: 45488 | D25: وليد توفيق | F25: 21200 | G25: =F25-E25+G24 -> 43578
C26: 45488 | D26: فاتوره فودافون | E26: 913 | G26: =F26-E26+G25 -> 42665
C27: 45491 | D27: نوالين صبحي | E27: 14450 | G27: =F27-E27+G26 -> 28215
C28: 45492 | D28: نولون احمد محمود | E28: 4280 | G28: =F28-E28+G27 -> 23935
C29: 45493 | D29: شحن رصيد محمود المهدي | E29: 100 | G29: =F29-E29+G28 -> 23835
C30: 45493 | D30: نولون عاطف تريلا | E30: 13000 | G30: =F30-E30+G29 -> 10835
C31: 45493 | D31: راشد الواسطي | F31: 19000 | G31: =F31-E31+G30 -> 29835
C32: 45493 | D32: راشد الواسطي | F32: 20590 | G32: =F32-E32+G31 -> 50425
C33: 45493 | D33: نولون نقله جيوشي راحت لعبداللاه | E33: 12000 | G33: =F33-E33+G32 -> 38425
C34: 45494 | D34: فاتوره فودافون | E34: 2600 | G34: =F34-E34+G33 -> 35825
C35: 45494 | D35: نولون طارق رفعت | E35: 11000 | G35: =F35-E35+G34 -> 24825
C36: 45495 | D36: نولون مصطفي بركات | E36: 4200 | G36: =F36-E36+G35 -> 20625
C37: 45498 | D37: نولون عاطف تريلا | E37: 12000 | G37: =F37-E37+G36 -> 8625
C38: 45501 | D38: احمد هيبك الكلابات | F38: 4000 | G38: =F38-E38+G37 -> 12625
C39: 45501 | D39: احمد هيبك الكلابات | F39: 2375 | G39: =F39-E39+G38 -> 15000
C40: 45502 | D40: حسين اسيوط الجديده تاجر اسمنت | F40: 12000 | G40: =F40-E40+G39 -> 27000
C41: 45502 | D41: نولون علي فروجه | E41: 2800 | G41: =F41-E41+G40 -> 24200
C42: 45503 | D42: سليم يوسف مصاريف | E42: 2000 | G42: =F42-E42+G41 -> 22200
C43: 45503 | D43: نوالين صبحي | E43: 14700 | G43: =F43-E43+G42 -> 7500
...

Sheet 11
C3: اتصالات كاش
E5: =SUM(E8:E999) -> 3008032 | F5: =SUM(F8:F999) -> 3038999 | G5: =F5-E5 -> 30967 | I5: الصفحة الرئيسية
C6: التاريخ | D6: الاسم | E6: الحركة | G6: الرصيد
E7: مدين | F7: دائن
D8: رصيد افتتاحي | G8: =F8-E8 -> 0
G9: =F9-E9+G8 -> 0
G10: =F10-E10+G9 -> 0
D11: (رصيد سابق) | F11: 6250 | G11: =F11-E11+G10 -> 6250
C12: 45532 | D12: على ابو خريبه ( تحصيل اسمنت ) | F12: 13000 | G12: =F12-E12+G11 -> 19250
C13: 45534 | D13: على ابو خريبه ( تحصيل اسمنت ) | F13: 10000 | G13: =F13-E13+G12 -> 29250
C14: 45537 | D14: على ابو خريبه ( تحصيل اسمنت ) | F14: 10000 | G14: =F14-E14+G13 -> 39250
C15: 45540 | D15: على ابو خريبه ( تحصيل اسمنت ) بأجمالى (44000) | F15: 11000 | G15: =F15-E15+G14 -> 50250
C16: 45910 | D16: مجهول (محفظه اتصالات كاش) | F16: 3845 | G16: =F16-E16+G15 -> 54095
C17: 45551 | D17: مصطفى الاكثر تميز (مقاوم تعمير) | F17: 35000 | G17: =F17-E17+G16 -> 89095
C18: 45551 | D18: عاطف شكرى (نولون 40طن احمد جابر والعرب) | E18: 4615 | G18: =F18-E18+G17 -> 84480
C19: 45552 | D19: على ابو خريبه | F19: 11000 | G19: =F19-E19+G18 -> 95480
C20: 45554 | D20: صبحى (نولون) | E20: 60000 | G20: =F20-E20+G19 -> 35480
C21: 45554 | D21: على ابو خريبه ( حديد ) | F21: 10000 | G21: =F21-E21+G20 -> 45480
C22: 45554 | D22: رسوم | E22: 15 | G22: =F22-E22+G21 -> 45465
C23: 45554 | D23: نولون عاطف مصطفى عبد الرسول (نقله جيوشى 50370) | E23: 13500 | G23: =F23-E23+G22 -> 31965
C24: 45556 | D24: ماهر مجدى | F24: 10000 | G24: =F24-E24+G23 -> 41965
C25: 45556 | D25: كيرلس موسى سباكه | F25: 10000 | G25: =F25-E25+G24 -> 51965
C26: 45558 | D26: ماهر مجدى | F26: 25200 | G26: =F26-E26+G25 -> 77165
C27: 45558 | D27: خالد ابو غلمى (عملاء 23-9-2024) | F27: 15000 | G27: =F27-E27+G26 -> 92165
C28: 45561 | D28: صبحى (نولون) | E28: 50000 | G28: =F28-E28+G27 -> 42165
C29: 45561 | D29: نولون عاطف شكرى | E29: 4400 | G29: =F29-E29+G28 -> 37765
C30: 45561 | D30: نولون محمد ثروت | E30: 3000 | G30: =F30-E30+G29 -> 34765
C31: 45561 | D31: رسوم | E31: 60 | G31: =F31-E31+G30 -> 34705
C32: 45564 | D32: شحن كارت كهرباء للمكتب | E32: 1065 | G32: =F32-E32+G31 -> 33640
C33: 45564 | D33: نولون طارق رفعت | E33: 3000 | G33: =F33-E33+G32 -> 30640
C34: 45568 | D34: حسين كمال اسيوط الجديده تمن 10 طن مقاوم مصريين | F34: 26200 | G34: =F34-E34+G33 -> 56840
C35: 45568 | D35: حسن ابو خريبه | F35: 20000 | G35: =F35-E35+G34 -> 76840
C36: 45569 | D36: صبحى (نولون) | E36: 30000 | G36: =F36-E36+G35 -> 46840
C37: 45574 | D37: احمد فوزى المهركه | F37: 16000 | G37: =F37-E37+G36 -> 62840
C38: 45574 | D38: صبحى (نولون) | E38: 15000 | G38: =F38-E38+G37 -> 47840
C39: 45574 | D39: نولون السهم محمود خالد | E39: 30000 | G39: =F39-E39+G38 -> 17840
C40: 45575 | D40: جمال الساحل | F40: 5660 | G40: =F40-E40+G39 -> 23500
C41: 45575 | D41: جمال الساحل | F41: 30000 | G41: =F41-E41+G40 -> 53500
C42: 45576 | D42: صبحى (نولون) | E42: 17800 | G42: =F42-E42+G41 -> 35700
C43: 45576 | D43: صبحى (نولون) | E43: 14650 | G43: =F43-E43+G42 -> 21050
...

Sheet 12
C3: البريد المصرى
E5: =SUM(E8:E1000) -> 15457953 | F5: =SUM(F8:F1000) -> 15593264 | G5: =F5-E5 -> 135311 | I5: الصفحة الرئيسية
C6: التاريخ | D6: الاسم | E6: الحركة | G6: الرصيد
E7: مدين | F7: دائن
D8: رصيد افتتاحي | F8: 129697 | G8: =F8-E8 -> 129697
C9: 45568 | D9: توريد اسمنت المصريين | E9: 129000 | G9: =F9-E9+G8 -> 697
C10: 45572 | D10: سليمان الاطاوله | F10: 50000 | G10: =F10-E10+G9 -> 50697
C11: 45573 | D11: سحب نقدى واصل يوميه يوسف | E11: 50000 | G11: =F11-E11+G10 -> 697
C12: 45574 | D12: سيد حسين مشرف | F12: 70000 | G12: =F12-E12+G11 -> 70697
C13: 45574 | D13: سحب نقدى واصل يوميه يوسف | E13: 100000 | G13: =F13-E13+G12 -> -29303
C14: 45574 | D14: سليمان الاطاوله | F14: 40000 | G14: =F14-E14+G13 -> 10697
C15: 45575 | D15: سليمان الاطاوله | F15: 30000 | G15: =F15-E15+G14 -> 40697
C16: 45580 | D16: سليمان الاطاوله | F16: 150000 | G16: =F16-E16+G15 -> 190697
C17: 45584 | D17: سليمان الاطاوله | F17: 50000 | G17: =F17-E17+G16 -> 240697
C18: 45578 | D18: سليمان الاطاوله | F18: 90000 | G18: =F18-E18+G17 -> 330697
C19: 45585 | D19: سحب نقدى واصل من يوميه يوسف | E19: 150000 | G19: =F19-E19+G18 -> 180697
C20: 45586 | D20: سحب نقدى واصل من يوميه يوسف | E20: 150000 | G20: =F20-E20+G19 -> 30697
C21: 45586 | D21: مصروفات بنكيه | E21: 414 | G21: =F21-E21+G20 -> 30283
C22: 45586 | D22: سيد حسين مشرف | F22: 9600 | G22: =F22-E22+G21 -> 39883
C23: 45588 | D23: سليمان الاطاوله | F23: 140000 | G23: =F23-E23+G22 -> 179883
C24: 45592 | D24: سحب نقدى واصل من يوميه يوسف | E24: 150000 | G24: =F24-E24+G23 -> 29883
C25: 45593 | D25: مجدى يوسف البدارى | F25: 135500 | G25: =F25-E25+G24 -> 165383
C26: 45594 | D26: سحب نقدى واصل من يوميه يوسف | E26: 150000 | G26: =F26-E26+G25 -> 15383
C27: 45596 | D27: سليمان الاطاوله | F27: 90000 | G27: =F27-E27+G26 -> 105383
C28: 45599 | D28: سحب نقدى واصل من يوميه يوسف | E28: 105005 | G28: =F28-E28+G27 -> 378
C29: 45599 | D29: مصاريف بريد | E29: 120 | G29: =F29-E29+G28 -> 258
C30: 45600 | D30: سيد حسين مشرف | F30: 99000 | G30: =F30-E30+G29 -> 99258
C31: 45601 | D31: مجدى يوسف البدارى | F31: 135000 | G31: =F31-E31+G30 -> 234258
C32: 45601 | D32: سحب نقدى واصل من يوميه يوسف | E32: 150005 | G32: =F32-E32+G31 -> 84253
C33: 45603 | D33: سليمان الاطاوله | F33: 50000 | G33: =F33-E33+G32 -> 134253
C34: 45606 | D34: سحب نقدى واصل من يوميه يوسف | E34: 130005 | G34: =F34-E34+G33 -> 4248
C35: 45606 | D35: مصاريف بريد | E35: 92 | G35: =F35-E35+G34 -> 4156
C36: 45607 | D36: سليمان الاطاوله | F36: 300000 | G36: =F36-E36+G35 -> 304156
C37: 45607 | D37: سيد حسين مشرف | F37: 58000 | G37: =F37-E37+G36 -> 362156
C38: 45608 | D38: سليمان الاطاوله | F38: 90000 | G38: =F38-E38+G37 -> 452156
C39: 45608 | D39: خالد مدبولى بصره | F39: 343000 | G39: =F39-E39+G38 -> 795156
C40: 45608 | D40: سحب نقدى واصل من يوميه يوسف | E40: 150005 | G40: =F40-E40+G39 -> 645151
C41: 45608 | D41: اسمنت التعمير | E41: 644500 | G41: =F41-E41+G40 -> 651
C42: 45609 | D42: ممتاز العفادره | F42: 71000 | G42: =F42-E42+G41 -> 71651
C43: 45610 | D43: سليمان الاطاوله | F43: 70000 | G43: =F43-E43+G42 -> 141651
...

Sheet 13
C3: فودافون كاش (جيمى)
E5: =SUM(E8:E1000) -> 1692263 | F5: =SUM(F8:F1000) -> 1709284 | G5: =F5-E5 -> 17021 | I5: الصفحة الرئيسية
C6: التاريخ | D6: الاسم | E6: الحركة | G6: الرصيد
E7: مدين | F7: دائن
D8: رصيد افتتاحي | G8: =F8-E8 -> 0
C9: 45809 | D9: حسن يوسف | F9: 33800 | G9: =F9-E9+G8 -> 33800
C10: 45809 | D10: نولون تبع صبحى | E10: 15600 | G10: =F10-E10+G9 -> 18200
C11: 45811 | D11: نولون تبع صبحى | E11: 8000 | G11: =F11-E11+G10 -> 10200
C12: 45811 | D12: بطاريه العربيه النص | E12: 4000 | G12: =F12-E12+G11 -> 6200
C13: 45823 | D13: تصليح العربيه النص الخضراء | E13: 1000 | G13: =F13-E13+G12 -> 5200
C14: 45824 | D14: حسن ابو خريبه | F14: 15000 | G14: =F14-E14+G13 -> 20200
C15: 45824 | D15: حسن ابو خريبه | F15: 4000 | G15: =F15-E15+G14 -> 24200
C16: 45824 | D16: حسن ابو خريبه | F16: 40000 | G16: =F16-E16+G15 -> 64200
C17: 45824 | D17: نولون حسنى نقله اللفف | E17: 15000 | G17: =F17-E17+G16 -> 49200
C18: 45824 | D18: نولون محمد عماد اسمنت المصريين | E18: 9350 | G18: =F18-E18+G17 -> 39850
C19: 45824 | D19: نولون على حمدان اسمنت المصريين | E19: 9000 | G19: =F19-E19+G18 -> 30850
C20: 45825 | D20: حسين كمال اسيوط الجديدة | F20: 46000 | G20: =F20-E20+G19 -> 76850
C21: 45825 | D21: فاتوره فودافون (الشركة) | E21: 1666 | G21: =F21-E21+G20 -> 75184
C22: 45826 | D22: عمرو عبدالناصر (عهده الترلة الزرقاء) | E22: 10000 | G22: =F22-E22+G21 -> 65184
C23: 45827 | D23: نولون محمد عماد | E23: 9425 | G23: =F23-E23+G22 -> 55759
C24: 45827 | D24: نولون علاء سيد شوقى | E24: 18840 | G24: =F24-E24+G23 -> 36919
C25: 45827 | D25: نولون 60 طن عاده من الشيخ جمال واصل شريف الغول | E25: 20400 | G25: =F25-E25+G24 -> 16519
C26: 45829 | D26: نولون وائل جميل نقله سايب راحت المهندس مصطفى فتحى محطه الاعمار | E26: 16000 | G26: =F26-E26+G25 -> 519
C27: 45833 | D27: من اتصالات كاش (سليم) | F27: 18000 | G27: =F27-E27+G26 -> 18519
C28: 45833 | D28: نولون وائل تبع هشام عكيوه 50 طن اسمنت مقاوم اسيوط | E28: 8000 | G28: =F28-E28+G27 -> 10519
C29: 45838 | D29: نولون على فروجه | E29: 1000 | G29: =F29-E29+G28 -> 9519
C30: 45838 | D30: نولون محمد رمضان (حديد جيوشى) | E30: 5910 | G30: =F30-E30+G29 -> 3609
C31: 45838 | D31: مصاريف تحويل | E31: 22 | G31: =F31-E31+G30 -> 3587
C32: 45848 | D32: عبدالرحيم الساحل | F32: 50000 | G32: =F32-E32+G31 -> 53587
C33: 45848 | D33: حسام زكى الساحل | F33: 30800 | G33: =F33-E33+G32 -> 84387
C34: 45848 | D34: حسام زكى الساحل | F34: 9000 | G34: =F34-E34+G33 -> 93387
C35: 45851 | D35: دعايه واعلان | E35: 250 | G35: =F35-E35+G34 -> 93137
C36: 45851 | D36: (نولون شحاته نقله بيانكو المخزن) و (حمل 15 طرد لصفوت سمعان ) | E36: 18500 | G36: =F36-E36+G35 -> 74637
C37: 45852 | D37: تصليح ماستر العربيه النص | E37: 2700 | G37: =F37-E37+G36 -> 71937
C38: 45852 | D38: (نولون ماهر هريدى 30×135) رايحه ل (مؤمن المطيعه) | E38: 4050 | G38: =F38-E38+G37 -> 67887
C39: 45852 | D39: نولون وتعتيق (طارق رفعت) او (محمود فتحى) (150×25)(18×25) | E39: 4200 | G39: =F39-E39+G38 -> 63687
C40: 45852 | D40: نولون محمد سالم يونس (عربيه رجب) | E40: 21000 | G40: =F40-E40+G39 -> 42687
C41: 45852 | D41: مصاريف تحويل | E41: 34 | G41: =F41-E41+G40 -> 42653
C42: 45854 | D42: نولون مصطفى سمير تبع عم صبحى (نقله العز) | E42: 12500 | G42: =F42-E42+G41 -> 30153
C43: 45854 | D43: نولون نقلتين السائب (شركة البيان) | E43: 19000 | G43: =F43-E43+G42 -> 11153
...

Sheet 14
C3: فودافون كاش (يوسف يوسف)
E5: =SUM(E8:E1000) -> 29200 | F5: =SUM(F8:F1000) -> 53195 | G5: =F5-E5 -> 23995 | I5: الصفحة الرئيسية
C6: التاريخ | D6: الاسم | E6: الحركة | G6: الرصيد
E7: مدين | F7: دائن
D8: رصيد افتتاحي | G8: =F8-E8 -> 0
C9: 45824 | D9: حسام زكى الساحل | F9: 9500 | G9: =F9-E9+G8 -> 9500
C10: 45824 | D10: حسام زكى الساحل | F10: 10000 | G10: =F10-E10+G9 -> 19500
C11: 45824 | D11: حسام زكى الساحل | F11: 10000 | G11: =F11-E11+G10 -> 29500
C12: 45831 | D12: نولون الحسن احمد فرغلى | E12: 14500 | G12: =F12-E12+G11 -> 15000
C13: 45834 | D13: نولون محروس محمد (نقله الكانات) | E13: 14700 | G13: =F13-E13+G12 -> 300
C14: 45972 | D14: احمد شعبان | F14: 5200 | G14: =F14-E14+G13 -> 5500
C15: 45973 | D15: صلاح عبدالهادى | F15: 3365 | G15: =F15-E15+G14 -> 8865
C16: 46017 | D16: محمد شحاته ابو خريبه | F16: 15130 | G16: =F16-E16+G15 -> 23995
G17: =F17-E17+G16 -> 23995
G18: =F18-E18+G17 -> 23995
G19: =F19-E19+G18 -> 23995
G20: =F20-E20+G19 -> 23995
G21: =F21-E21+G20 -> 23995
G22: =F22-E22+G21 -> 23995
G23: =F23-E23+G22 -> 23995
G24: =F24-E24+G23 -> 23995
G25: =F25-E25+G24 -> 23995
G26: =F26-E26+G25 -> 23995
G27: =F27-E27+G26 -> 23995
G28: =F28-E28+G27 -> 23995
... G1000: =F1000-E1000+G999 -> 23995

Sheet 15
C3: بنك الاهلى (يوسف يوسف)
E5: =SUM(E8:E1000) -> 20055180 | F5: =SUM(F8:F1000) -> 20056830 | G5: =F5-E5 -> 1650 | I5: الصفحة الرئيسية
C6: التاريخ | D6: الاسم | E6: الحركة | G6: الرصيد
E7: مدين | F7: دائن
D8: رصيد افتتاحي | G8: =F8-E8 -> 0
C9: 45844 | D9: من بنك الاهلى (سليم) | F9: 1350000 | G9: =F9-E9+G8 -> 1350000
C10: 45844 | D10: من بنك الاسكندريه (سليم) | F10: 2435000 | G10: =F10-E10+G9 -> 3785000
C11: 45844 | D11: ايداع نقدى من البيت منهم (81 الف من عبدالرازق) | F11: 2901830 | G11: =F11-E11+G10 -> 6686830
C12: 45844 | D12: حديد عز | E12: 6685000 | G12: =F12-E12+G11 -> 1830
C13: 45844 | D13: مصروفات بنكيه | E13: 180 | G13: =F13-E13+G12 -> 1650
C14: 45853 | D14: من بنك الاهلى (سليم) | F14: 1607000 | G14: =F14-E14+G13 -> 1608650
C15: 45853 | D15: من بنك مصر (يوسف) | F15: 1450000 | G15: =F15-E15+G14 -> 3058650
C16: 45853 | D16: من بنك الاسكندريه (يوسف) | F16: 3000000 | G16: =F16-E16+G15 -> 6058650
C17: 45853 | D17: من بنك الاسكندريه (يوسف) | F17: 628000 | G17: =F17-E17+G16 -> 6686650
C18: 45853 | D18: حديد عز | E18: 6685000 | G18: =F18-E18+G17 -> 1650
C19: 45866 | D19: من بنك الاسكندريه (يوسف) | F19: 1860000 | G19: =F19-E19+G18 -> 1861650
C20: 45866 | D20: من بنك الاسكندريه (يوسف) | F20: 3000000 | G20: =F20-E20+G19 -> 4861650
C21: 45866 | D21: من بنك مصر (يوسف) | F21: 1825000 | G21: =F21-E21+G20 -> 6686650
C22: 45866 | D22: شيك حديد عز | E22: 6685000 | G22: =F22-E22+G21 -> 1650
G23: =F23-E23+G22 -> 1650
G24: =F24-E24+G23 -> 1650
G25: =F25-E25+G24 -> 1650
G26: =F26-E26+G25 -> 1650
G27: =F27-E27+G26 -> 1650
G28: =F28-E28+G27 -> 1650
G29: =F29-E29+G28 -> 1650
G30: =F30-E30+G29 -> 1650
G31: =F31-E31+G30 -> 1650
G32: =F32-E32+G31 -> 1650
G33: =F33-E33+G32 -> 1650
G34: =F34-E34+G33 -> 1650
... G1000: =F1000-E1000+G999 -> 1650

Sheet 16
C3: بنك العقارى المصرى العربى
E5: =SUM(E8:E1000) -> 2950000 | F5: =SUM(F8:F1000) -> 3000000 | G5: =F5-E5 -> 50000 | I5: الصفحة الرئيسية
C6: التاريخ | D6: الاسم | E6: الحركة | G6: الرصيد
E7: مدين | F7: دائن
D8: رصيد افتتاحي | G8: =F8-E8 -> 0
C9: 45922 | D9: من بنك مصر الشرق | F9: 2000000 | G9: =F9-E9+G8 -> 2000000
C10: 45929 | D10: الى بنك مصر يوسف | E10: 1900000 | G10: =E10-F10+G9 -> 3900000
C11: 45931 | D11: جمال سيد سعد | F11: 1000000 | G11: =E11-F11+G10 -> 2900000
C12: 45931 | D12: الرضا ستيل | E12: 1050000 | G12: =E12-F12+G11 -> 3950000
G13: =E13-F13+G12 -> 3950000
G14: =E14-F14+G13 -> 3950000
G15: =E15-F15+G14 -> 3950000
G16: =E16-F16+G15 -> 3950000
G17: =E17-F17+G16 -> 3950000
G18: =E18-F18+G17 -> 3950000
G19: =E19-F19+G18 -> 3950000
G20: =E20-F20+G19 -> 3950000
G21: =E21-F21+G20 -> 3950000
G22: =E22-F22+G21 -> 3950000
G23: =E23-F23+G22 -> 3950000
G24: =E24-F24+G23 -> 3950000
... G1000: =E1000-F1000+G999 -> 3950000

Sheet 17
C3: فودافون كاش ( احمد علاء )
E5: =SUM(E8:E1000) -> 67329 | F5: =SUM(F8:F1000) -> 67355 | G5: =F5-E5 -> 26 | I5: الصفحة الرئيسية
C6: التاريخ | D6: الاسم | E6: الحركة | G6: الرصيد
E7: مدين | F7: دائن
D8: رصيد افتتاحي | F8: 2355 | G8: =F8-E8 -> 2355
C9: 46009 | D9: نولون ابراهيم احمد | E9: 2340 | G9: =F9-E9+G8 -> 15
C10: 46013 | D10: يوسف ريفا | F10: 5000 | G10: =F10-E10+G9 -> 5015
C11: 46013 | D11: نولون محمود فتحى | E11: 3500 | G11: =F11-E11+G10 -> 1515
C12: 46013 | D12: رسوم تحويل | E12: 30 | G12: =F12-E12+G11 -> 1485
C13: 46014 | D13: باقى حساب عامر | E13: 1130 | G13: =F13-E13+G12 -> 355
C14: 46022 | D14: من فودافون كاش سليم | F14: 30000 | G14: =F14-E14+G13 -> 30355
C15: 46023 | D15: نولون شعبان ابراهيم | E15: 17350 | G15: =F15-E15+G14 -> 13005
C16: 46025 | D16: محمد عبدالناصر ( سواق الترلة الزرقاء من المرتب ) | E16: 7000 | G16: =F16-E16+G15 -> 6005
C17: 46037 | D17: باقى نولون رمضان شفيق | E17: 500 | G17: =F17-E17+G16 -> 5505
C18: 46036 | D18: نولون عمر بدرى حجازى | E18: 3625 | G18: =F18-E18+G17 -> 1880
C19: 46041 | D19: عهده عبد المعز محمد ( سواق الترلة ) | E19: 1000 | G19: =F19-E19+G18 -> 880
C20: 46043 | D20: سليم يوسف مصاريف | E20: 200 | G20: =F20-E20+G19 -> 680
C21: 46047 | D21: قهوه على محمد رمضان | E21: 200 | G21: =F21-E21+G20 -> 480
C22: 46048 | D22: عبد المعز محمد محمود السواق | E22: 200 | G22: =F22-E22+G21 -> 280
C23: 46088 | D23: من محفظه فودافون كاش سليم | F23: 30000 | G23: =F23-E23+G22 -> 30280
C24: 46088 | D24: عهده نولون مصطفى جمال فرغلى | E24: 1000 | G24: =F24-E24+G23 -> 29280
C25: 46088 | D25: رسوم تحويل | E25: 54 | G25: =F25-E25+G24 -> 29226
C26: 46088 | D26: نولون محمد مصطفى عبدالرشيد | E26: 24950 | G26: =F26-E26+G25 -> 4276
C27: 46088 | D27: باقى نولون هانى رمزى ( فاضله 750 جنيه ) | E27: 4250 | G27: =F27-E27+G26 -> 26
G28: =F28-E28+G27 -> 26
G29: =F29-E29+G28 -> 26
G30: =F30-E30+G29 -> 26
G31: =F31-E31+G30 -> 26
G32: =F32-E32+G31 -> 26
G33: =F33-E33+G32 -> 26
G34: =F34-E34+G33 -> 26
G35: =F35-E35+G34 -> 26
G36: =F36-E36+G35 -> 26
G37: =F37-E37+G36 -> 26
G38: =F38-E38+G37 -> 26
G39: =F39-E39+G38 -> 26
... G1000: =F1000-E1000+G999 -> 26

Sheet 18
C3: بنك الأسكان والتعمير
E5: =SUM(E8:E1000) -> 10490000 | F5: =SUM(F8:F1000) -> 10561500 | G5: =F5-E5 -> 71500 | I5: الصفحة الرئيسية
C6: التاريخ | D6: الاسم | E6: الحركة | G6: الرصيد
E7: مدين | F7: دائن
D8: رصيد افتتاحي | G8: =F8-E8 -> 0
C9: 46049 | D9: من بنك ابو ظبى الاول ( مصر ) | F9: 1000000 | G9: =F9-E9+G8 -> 1000000
C10: 46050 | D10: من بنك ابو ظبى الاول ( مصر ) | F10: 500000 | G10: =F10-E10+G9 -> 1500000
C11: 46050 | D11: من بنك مصر الشرق | F11: 3000000 | G11: =F11-E11+G10 -> 4500000
C12: 46050 | D12: من بنك مصر الشرق | F12: 3000000 | G12: =F12-E12+G11 -> 7500000
C13: 46050 | D13: من بنك مصر الشرق | F13: 3000000 | G13: =F13-E13+G12 -> 10500000
C14: 46054 | D14: الى بنك الاسكندريه سليم | E14: 10490000 | G14: =F14-E14+G13 -> 10000
C15: 46054 | D15: هانى عبد التواب | F15: 3500 | G15: =F15-E15+G14 -> 13500
C16: 46054 | D16: هانى عبد التواب | F16: 58000 | G16: =F16-E16+G15 -> 71500
G17: =F17-E17+G16 -> 71500
G18: =F18-E18+G17 -> 71500
G19: =F19-E19+G18 -> 71500
G20: =F20-E20+G19 -> 71500
G21: =F21-E21+G20 -> 71500
G22: =F22-E22+G21 -> 71500
G23: =F23-E23+G22 -> 71500
G24: =F24-E24+G23 -> 71500
G25: =F25-E25+G24 -> 71500
G26: =F26-E26+G25 -> 71500
G27: =F27-E27+G26 -> 71500
G28: =F28-E28+G27 -> 71500
... G1000: =F1000-E1000+G999 -> 71500

Sheet 19
E5: =SUM(E8:E1000) -> 0 | F5: =SUM(F8:F1000) -> 0 | G5: =F5-E5 -> 0 | I5: الصفحة الرئيسية
C6: التاريخ | D6: الاسم | E6: الحركة | G6: الرصيد
E7: مدين | F7: دائن
D8: رصيد افتتاحي | G8: =F8-E8 -> 0
G9: =E9-F9+G8 -> 0
G10: =E10-F10+G9 -> 0
G11: =E11-F11+G10 -> 0
G12: =E12-F12+G11 -> 0
G13: =E13-F13+G12 -> 0
G14: =E14-F14+G13 -> 0
G15: =E15-F15+G14 -> 0
G16: =E16-F16+G15 -> 0
G17: =E17-F17+G16 -> 0
G18: =E18-F18+G17 -> 0
G19: =E19-F19+G18 -> 0
G20: =E20-F20+G19 -> 0
... G1000: =E1000-F1000+G999 -> 0

Sheet 20
E5: =SUM(E8:E1000) -> 0 | F5: =SUM(F8:F1000) -> 0 | G5: =F5-E5 -> 0 | I5: الصفحة الرئيسية
C6: التاريخ | D6: الاسم | E6: الحركة | G6: الرصيد
E7: مدين | F7: دائن
D8: رصيد افتتاحي | G8: =F8-E8 -> 0
G9: =E9-F9+G8 -> 0
G10: =E10-F10+G9 -> 0
G11: =E11-F11+G10 -> 0
G12: =E12-F12+G11 -> 0
G13: =E13-F13+G12 -> 0
G14: =E14-F14+G13 -> 0
G15: =E15-F15+G14 -> 0
G16: =E16-F16+G15 -> 0
G17: =E17-F17+G16 -> 0
G18: =E18-F18+G17 -> 0
G19: =E19-F19+G18 -> 0
G20: =E20-F20+G19 -> 0
... G1000: =E1000-F1000+G999 -> 0

Sheet 21
E5: =SUM(E8:E1000) -> 0 | F5: =SUM(F8:F1000) -> 0 | G5: =F5-E5 -> 0 | I5: الصفحة الرئيسية
C6: التاريخ | D6: الاسم | E6: الحركة | G6: الرصيد
E7: مدين | F7: دائن
D8: رصيد افتتاحي | G8: =F8-E8 -> 0
G9: =E9-F9+G8 -> 0
G10: =E10-F10+G9 -> 0
G11: =E11-F11+G10 -> 0
G12: =E12-F12+G11 -> 0
G13: =E13-F13+G12 -> 0
G14: =E14-F14+G13 -> 0
G15: =E15-F15+G14 -> 0
G16: =E16-F16+G15 -> 0
G17: =E17-F17+G16 -> 0
G18: =E18-F18+G17 -> 0
G19: =E19-F19+G18 -> 0
G20: =E20-F20+G19 -> 0
... G1000: =E1000-F1000+G999 -> 0

Sheet 22
E5: =SUM(E8:E1000) -> 0 | F5: =SUM(F8:F1000) -> 0 | G5: =F5-E5 -> 0 | I5: الصفحة الرئيسية
C6: التاريخ | D6: الاسم | E6: الحركة | G6: الرصيد
E7: مدين | F7: دائن
D8: رصيد افتتاحي | G8: =F8-E8 -> 0
G9: =E9-F9+G8 -> 0
G10: =E10-F10+G9 -> 0
G11: =E11-F11+G10 -> 0
G12: =E12-F12+G11 -> 0
G13: =E13-F13+G12 -> 0
G14: =E14-F14+G13 -> 0
G15: =E15-F15+G14 -> 0
G16: =E16-F16+G15 -> 0
G17: =E17-F17+G16 -> 0
G18: =E18-F18+G17 -> 0
G19: =E19-F19+G18 -> 0
G20: =E20-F20+G19 -> 0
... G1000: =E1000-F1000+G999 -> 0

Sheet Sheet1
